Workbook

Sheet README
A1: CS0073 Technical Assessment, Module 2: Diagnostic Analytics and Statistical Inference
A3: Name | B3: Dawn Andrei Pamesa
A4: Section | B4: TS31
A5: Professor | B5: Jeneffer Sabonsolin
A6: Date Performed | B6: September 28, 2026
A7: Date Submitted
A8: Dataset | B8: Customer_Satisfaction.xlsx: restaurant survey, 405 respondents, 13 items on a 1 to 7 scale
A9: Companion file | B9: PAMESA - M2-Technical - Full.ipynb (same analysis in Python, plus Tukey post-hoc, Shapiro-Wilk and Spearman, which Excel cannot compute directly)
A11: Sheets, in order
A12: Questions | B12: The codebook: what each item x12 to x24 asks.
A13: Data | B13: The 405 survey responses (id and x12 to x24), copied from the dataset.
A14: Cleaning | B14: Data quality checks: missing values, duplicate ids, impossible answers.
A15: Descriptives | B15: Count, mean, SD, median, min and max of every item.
A16: Correlation | B16: Part A: 13 x 13 Pearson correlation matrix and the table of each perception vs the three outcomes, with p-values.
A17: ANOVA Data | B17: Freshness (x15) and satisfaction (x22) sorted by freshness, with helper columns.
A18: ANOVA | B18: Part B: hypotheses, group statistics, Levene's test, one-way ANOVA, Welch's ANOVA, Kruskal-Wallis.
A19: Charts | B19: Mean satisfaction by freshness level; correlation of each perception with satisfaction.
A20: Summary | B20: Every key number in one place, with a plain-language note on how to defend it.
A21: AI Appendix | B21: AI tools and prompts used, verification steps and corrections.
A23: Color key
A24: Blue text | B24: Raw data or a value you may change (such as alpha)
A25: Black text | B25: Formula
A26: Green text | B26: Formula that links to another sheet

Sheet Questions
A1: Codebook (from the dataset's Questions sheet)
A3: Code | B3: Question | C3: Scale
A4: x12 | B4: The restaurant has friendly employees | C4: 1 = Strongly Disagree ... 7 = Strongly Agree
A5: x13 | B5: The restaurant is a fun place to eat | C5: 1 = Strongly Disagree ... 7 = Strongly Agree
A6: x14 | B6: The restaurant has large size portions | C6: 1 = Strongly Disagree ... 7 = Strongly Agree
A7: x15 | B7: The restaurant has fresh food | C7: 1 = Strongly Disagree ... 7 = Strongly Agree
A8: x16 | B8: The restaurant has reasonable prices | C8: 1 = Strongly Disagree ... 7 = Strongly Agree
A9: x17 | B9: The restaurant has an attractive interior | C9: 1 = Strongly Disagree ... 7 = Strongly Agree
A10: x18 | B10: The restaurant has excellent food taste | C10: 1 = Strongly Disagree ... 7 = Strongly Agree
A11: x19 | B11: The restaurant has knowledgeable employees | C11: 1 = Strongly Disagree ... 7 = Strongly Agree
A12: x20 | B12: The restaurant serves food at the proper temperature | C12: 1 = Strongly Disagree ... 7 = Strongly Agree
A13: x21 | B13: The restaurant has quick service | C13: 1 = Strongly Disagree ... 7 = Strongly Agree
A14: x22 | B14: Satisfaction rating | C14: 1 = Not Satisfied at all ... 7 = Very Satisfied
... A16: x24 | B16: Likelihood to recommend | C16: 1 = Definitely Will Not Recommend ... 7 = Definitely Will Recommend

Sheet Data
A1: id | B1: x12 | C1: x13 | D1: x14 | E1: x15 | F1: x16 | G1: x17 | H1: x18 | I1: x19 | J1: x20 | K1: x21 | L1: x22 | M1: x23 | N1: x24
A2: 1 | B2: 5 | C2: 6 | D2: 4 | E2: 7 | F2: 4 | G2: 6 | H2: 6 | I2: 4 | J2: 4 | K2: 4 | L2: 4 | M2: 4 | N2: 3 | P2: Copied from Customer_Satisfaction.xlsx, sheet Survey Responses, columns A to N.
A3: 6 | B3: 3 | C3: 5 | D3: 6 | E3: 6 | F3: 6 | G3: 5 | H3: 7 | I3: 4 | J3: 7 | K3: 4 | L3: 6 | M3: 5 | N3: 5 | P3: Columns O to Q of that sheet hold the instructor's task note, not responses, so they are not copied.
A4: 7 | B4: 4 | C4: 6 | D4: 4 | E4: 6 | F4: 4 | G4: 6 | H4: 6 | I4: 3 | J4: 4 | K4: 4 | L4: 4 | M4: 3 | N4: 2
A5: 9 | B5: 5 | C5: 5 | D5: 5 | E5: 7 | F5: 4 | G5: 5 | H5: 6 | I5: 4 | J5: 6 | K5: 7 | L5: 7 | M5: 7 | N5: 6
A6: 10 | B6: 4 | C6: 6 | D6: 5 | E6: 7 | F6: 5 | G6: 6 | H6: 7 | I6: 4 | J6: 6 | K6: 7 | L6: 6 | M6: 6 | N6: 6
A7: 15 | B7: 5 | C7: 5 | D7: 3 | E7: 5 | F7: 3 | G7: 5 | H7: 5 | I7: 4 | J7: 3 | K7: 7 | L7: 5 | M7: 4 | N7: 2
A8: 20 | B8: 5 | C8: 5 | D8: 4 | E8: 7 | F8: 4 | G8: 5 | H8: 6 | I8: 4 | J8: 3 | K8: 7 | L8: 4 | M8: 3 | N8: 2
A9: 26 | B9: 5 | C9: 6 | D9: 5 | E9: 7 | F9: 5 | G9: 6 | H9: 6 | I9: 6 | J9: 5 | K9: 7 | L9: 7 | M9: 6 | N9: 5
A10: 27 | B10: 5 | C10: 4 | D10: 3 | E10: 6 | F10: 3 | G10: 4 | H10: 6 | I10: 4 | J10: 5 | K10: 7 | L10: 6 | M10: 5 | N10: 4
A11: 28 | B11: 5 | C11: 6 | D11: 3 | E11: 7 | F11: 3 | G11: 6 | H11: 7 | I11: 7 | J11: 6 | K11: 7 | L11: 7 | M11: 7 | N11: 6
A12: 33 | B12: 5 | C12: 3 | D12: 5 | E12: 7 | F12: 5 | G12: 3 | H12: 7 | I12: 4 | J12: 7 | K12: 7 | L12: 5 | M12: 6 | N12: 4
A13: 34 | B13: 5 | C13: 3 | D13: 4 | E13: 7 | F13: 4 | G13: 3 | H13: 7 | I13: 4 | J13: 6 | K13: 7 | L13: 6 | M13: 6 | N13: 5
A14: 37 | B14: 5 | C14: 3 | D14: 4 | E14: 7 | F14: 4 | G14: 5 | H14: 5 | I14: 4 | J14: 5 | K14: 7 | L14: 7 | M14: 6 | N14: 6
A15: 39 | B15: 5 | C15: 4 | D15: 6 | E15: 7 | F15: 6 | G15: 5 | H15: 7 | I15: 7 | J15: 5 | K15: 7 | L15: 6 | M15: 6 | N15: 5
... A406: 405 | B406: 3 | C406: 4 | D406: 2 | E406: 4 | F406: 2 | G406: 3 | H406: 4 | I406: 4 | J406: 3 | K406: 4 | L406: 4 | M406: 3 | N406: 3

Sheet Cleaning
A1: Data Cleaning Checks
A2: All checks should read 405 rows and 0 problems.
A3: Check | B3: Result | C3: What the formula does
A4: Rows (respondents) | B4: =COUNT(Data!A2:A406) -> 405 | C4: Counts the ids.
A5: Missing values | B5: =COUNTBLANK(Data!B2:N406) -> 0 | C5: Counts empty cells in x12 to x24.
A6: Rows that share an id | B6: =SUMPRODUCT(--(COUNTIF(Data!A2:A406,Data!A2:A406)>1)) -> 0 | C6: Counts rows whose id appears more than once.
A7: Answers outside 1 to 7 | B7: =COUNTIF(Data!B2:N406,"<1")+COUNTIF(Data!B2:N406,">7") -> 0 | C7: Counts impossible answers.
A8: Non-whole-number answers | B8: =SUMPRODUCT(--(Data!B2:N406<>INT(Data!B2:N406))) -> 0 | C8: Counts answers with decimals.

Sheet Descriptives
A1: Descriptive Statistics
A2: Every item is on a 1 to 7 scale.
A3: Code | B3: Question | C3: n | D3: Mean | E3: SD | F3: Median | G3: Min | H3: Max
A4: x12 | B4: Friendly employees | C4: =COUNT(Data!B$2:B$406) -> 405 | D4: =AVERAGE(Data!B$2:B$406) -> 3.6395062 | E4: =_xlfn.STDEV.S(Data!B$2:B$406) -> 1.2098686 | F4: =MEDIAN(Data!B$2:B$406) -> 4 | G4: =MIN(Data!B$2:B$406) -> 1 | H4: =MAX(Data!B$2:B$406) -> 5
A5: x13 | B5: Fun place to eat | C5: =COUNT(Data!C$2:C$406) -> 405 | D5: =AVERAGE(Data!C$2:C$406) -> 4.637037 | E5: =_xlfn.STDEV.S(Data!C$2:C$406) -> 0.90876432 | F5: =MEDIAN(Data!C$2:C$406) -> 5 | G5: =MIN(Data!C$2:C$406) -> 2 | H5: =MAX(Data!C$2:C$406) -> 7
A6: x14 | B6: Large portions | C6: =COUNT(Data!D$2:D$406) -> 405 | D6: =AVERAGE(Data!D$2:D$406) -> 4.508642 | E6: =_xlfn.STDEV.S(Data!D$2:D$406) -> 1.3230812 | F6: =MEDIAN(Data!D$2:D$406) -> 5 | G6: =MIN(Data!D$2:D$406) -> 2 | H6: =MAX(Data!D$2:D$406) -> 6
A7: x15 | B7: Fresh food | C7: =COUNT(Data!E$2:E$406) -> 405 | D7: =AVERAGE(Data!E$2:E$406) -> 5.762963 | E7: =_xlfn.STDEV.S(Data!E$2:E$406) -> 1.1953338 | F7: =MEDIAN(Data!E$2:E$406) -> 6 | G7: =MIN(Data!E$2:E$406) -> 4 | H7: =MAX(Data!E$2:E$406) -> 7
A8: x16 | B8: Reasonable prices | C8: =COUNT(Data!F$2:F$406) -> 405 | D8: =AVERAGE(Data!F$2:F$406) -> 4.3382716 | E8: =_xlfn.STDEV.S(Data!F$2:F$406) -> 1.2374687 | F8: =MEDIAN(Data!F$2:F$406) -> 4 | G8: =MIN(Data!F$2:F$406) -> 2 | H8: =MAX(Data!F$2:F$406) -> 6
A9: x17 | B9: Attractive interior | C9: =COUNT(Data!G$2:G$406) -> 405 | D9: =AVERAGE(Data!G$2:G$406) -> 4.6962963 | E9: =_xlfn.STDEV.S(Data!G$2:G$406) -> 1.019178 | F9: =MEDIAN(Data!G$2:G$406) -> 5 | G9: =MIN(Data!G$2:G$406) -> 2 | H9: =MAX(Data!G$2:G$406) -> 7
A10: x18 | B10: Excellent food taste | C10: =COUNT(Data!H$2:H$406) -> 405 | D10: =AVERAGE(Data!H$2:H$406) -> 5.3111111 | E10: =_xlfn.STDEV.S(Data!H$2:H$406) -> 1.0840883 | F10: =MEDIAN(Data!H$2:H$406) -> 5 | G10: =MIN(Data!H$2:H$406) -> 3 | H10: =MAX(Data!H$2:H$406) -> 7
A11: x19 | B11: Knowledgeable employees | C11: =COUNT(Data!I$2:I$406) -> 405 | D11: =AVERAGE(Data!I$2:I$406) -> 3.5530864 | E11: =_xlfn.STDEV.S(Data!I$2:I$406) -> 1.5173164 | F11: =MEDIAN(Data!I$2:I$406) -> 4 | G11: =MIN(Data!I$2:I$406) -> 1 | H11: =MAX(Data!I$2:I$406) -> 7
A12: x20 | B12: Proper food temperature | C12: =COUNT(Data!J$2:J$406) -> 405 | D12: =AVERAGE(Data!J$2:J$406) -> 4.5234568 | E12: =_xlfn.STDEV.S(Data!J$2:J$406) -> 1.1678735 | F12: =MEDIAN(Data!J$2:J$406) -> 5 | G12: =MIN(Data!J$2:J$406) -> 2 | H12: =MAX(Data!J$2:J$406) -> 7
A13: x21 | B13: Quick service | C13: =COUNT(Data!K$2:K$406) -> 405 | D13: =AVERAGE(Data!K$2:K$406) -> 5.2098765 | E13: =_xlfn.STDEV.S(Data!K$2:K$406) -> 2.0387099 | F13: =MEDIAN(Data!K$2:K$406) -> 7 | G13: =MIN(Data!K$2:K$406) -> 1 | H13: =MAX(Data!K$2:K$406) -> 7
A14: x22 | B14: Satisfaction | C14: =COUNT(Data!L$2:L$406) -> 405 | D14: =AVERAGE(Data!L$2:L$406) -> 4.8296296 | E14: =_xlfn.STDEV.S(Data!L$2:L$406) -> 1.1183045 | F14: =MEDIAN(Data!L$2:L$406) -> 5 | G14: =MIN(Data!L$2:L$406) -> 3 | H14: =MAX(Data!L$2:L$406) -> 7
A15: x23 | B15: Likely to return | C15: =COUNT(Data!M$2:M$406) -> 405 | D15: =AVERAGE(Data!M$2:M$406) -> 4.4641975 | E15: =_xlfn.STDEV.S(Data!M$2:M$406) -> 1.104369 | F15: =MEDIAN(Data!M$2:M$406) -> 4 | G15: =MIN(Data!M$2:M$406) -> 2 | H15: =MAX(Data!M$2:M$406) -> 7
A16: x24 | B16: Likely to recommend | C16: =COUNT(Data!N$2:N$406) -> 405 | D16: =AVERAGE(Data!N$2:N$406) -> 3.7851852 | E16: =_xlfn.STDEV.S(Data!N$2:N$406) -> 1.1985048 | F16: =MEDIAN(Data!N$2:N$406) -> 4 | G16: =MIN(Data!N$2:N$406) -> 2 | H16: =MAX(Data!N$2:N$406) -> 7

Sheet Correlation
A1: Part A. Pearson Correlation Analysis
A2: Task in the dataset: correlate the perception indicators with each other and with satisfaction, return and recommend.
A3: n (respondents) | B3: =COUNT(Data!A2:A406) -> 405
A4: Alpha | B4: 0.05
A5: df = n - 2 | B5: =B3-2 -> 403
A6: Critical t (two-tailed) | B6: =_xlfn.T.INV.2T(B4,B5) -> 1.9658679
A7: Critical r (smallest significant |r|) | B7: =B6/SQRT(B6^2+B5) -> 0.097460664
B9: x12 | C9: x13 | D9: x14 | E9: x15 | F9: x16 | G9: x17 | H9: x18 | I9: x19 | J9: x20 | K9: x21 | L9: x22 | M9: x23 | N9: x24
A10: x12 Friendly employees | B10: =CORREL(Data!B$2:B$406,Data!B$2:B$406) -> 1 | C10: =CORREL(Data!B$2:B$406,Data!C$2:C$406) -> -0.15081897 | D10: =CORREL(Data!B$2:B$406,Data!D$2:D$406) -> -0.036706505 | E10: =CORREL(Data!B$2:B$406,Data!E$2:E$406) -> 0.36009881 | F10: =CORREL(Data!B$2:B$406,Data!F$2:F$406) -> -0.047304199 | G10: =CORREL(Data!B$2:B$406,Data!G$2:G$406) -> -0.11309748 | H10: =CORREL(Data!B$2:B$406,Data!H$2:H$406) -> 0.35558865 | I10: =CORREL(Data!B$2:B$406,Data!I$2:I$406) -> 0.60103012 | J10: =CORREL(Data!B$2:B$406,Data!J$2:J$406) -> 0.020013779 | K10: =CORREL(Data!B$2:B$406,Data!K$2:K$406) -> 0.81048299 | L10: =CORREL(Data!B$2:B$406,Data!L$2:L$406) -> 0.42466259 | M10: =CORREL(Data!B$2:B$406,Data!M$2:M$406) -> 0.36082335 | N10: =CORREL(Data!B$2:B$406,Data!N$2:N$406) -> 0.19056756
A11: x13 Fun place to eat | B11: =CORREL(Data!C$2:C$406,Data!B$2:B$406) -> -0.15081897 | C11: =CORREL(Data!C$2:C$406,Data!C$2:C$406) -> 1 | D11: =CORREL(Data!C$2:C$406,Data!D$2:D$406) -> 0.39066928 | E11: =CORREL(Data!C$2:C$406,Data!E$2:E$406) -> -0.011038807 | F11: =CORREL(Data!C$2:C$406,Data!F$2:F$406) -> 0.38458338 | G11: =CORREL(Data!C$2:C$406,Data!G$2:G$406) -> 0.6717471 | H11: =CORREL(Data!C$2:C$406,Data!H$2:H$406) -> 0.029479771 | I11: =CORREL(Data!C$2:C$406,Data!I$2:I$406) -> 0.12081759 | J11: =CORREL(Data!C$2:C$406,Data!J$2:J$406) -> 0.090836075 | K11: =CORREL(Data!C$2:C$406,Data!K$2:K$406) -> -0.053638604 | L11: =CORREL(Data!C$2:C$406,Data!L$2:L$406) -> 0.21909641 | M11: =CORREL(Data!C$2:C$406,Data!M$2:M$406) -> 0.22502167 | N11: =CORREL(Data!C$2:C$406,Data!N$2:N$406) -> 0.27367444
A12: x14 Large portions | B12: =CORREL(Data!D$2:D$406,Data!B$2:B$406) -> -0.036706505 | C12: =CORREL(Data!D$2:D$406,Data!C$2:C$406) -> 0.39066928 | D12: =CORREL(Data!D$2:D$406,Data!D$2:D$406) -> 1 | E12: =CORREL(Data!D$2:D$406,Data!E$2:E$406) -> 0.13902752 | F12: =CORREL(Data!D$2:D$406,Data!F$2:F$406) -> 0.9589669 | G12: =CORREL(Data!D$2:D$406,Data!G$2:G$406) -> 0.28555402 | H12: =CORREL(Data!D$2:D$406,Data!H$2:H$406) -> 0.039537901 | I12: =CORREL(Data!D$2:D$406,Data!I$2:I$406) -> 0.086387742 | J12: =CORREL(Data!D$2:D$406,Data!J$2:J$406) -> 0.080364128 | K12: =CORREL(Data!D$2:D$406,Data!K$2:K$406) -> 0.017220084 | L12: =CORREL(Data!D$2:D$406,Data!L$2:L$406) -> 0.30797615 | M12: =CORREL(Data!D$2:D$406,Data!M$2:M$406) -> 0.26829056 | N12: =CORREL(Data!D$2:D$406,Data!N$2:N$406) -> 0.30790267
A13: x15 Fresh food | B13: =CORREL(Data!E$2:E$406,Data!B$2:B$406) -> 0.36009881 | C13: =CORREL(Data!E$2:E$406,Data!C$2:C$406) -> -0.011038807 | D13: =CORREL(Data!E$2:E$406,Data!D$2:D$406) -> 0.13902752 | E13: =CORREL(Data!E$2:E$406,Data!E$2:E$406) -> 1 | F13: =CORREL(Data!E$2:E$406,Data!F$2:F$406) -> 0.16311141 | G13: =CORREL(Data!E$2:E$406,Data!G$2:G$406) -> -0.00031605663 | H13: =CORREL(Data!E$2:E$406,Data!H$2:H$406) -> 0.78863234 | I13: =CORREL(Data!E$2:E$406,Data!I$2:I$406) -> 0.39181483 | J13: =CORREL(Data!E$2:E$406,Data!J$2:J$406) -> 0.50223431 | K13: =CORREL(Data!E$2:E$406,Data!K$2:K$406) -> 0.11492684 | L13: =CORREL(Data!E$2:E$406,Data!L$2:L$406) -> 0.55855337 | M13: =CORREL(Data!E$2:E$406,Data!M$2:M$406) -> 0.49607151 | N13: =CORREL(Data!E$2:E$406,Data!N$2:N$406) -> 0.47061021
A14: x16 Reasonable prices | B14: =CORREL(Data!F$2:F$406,Data!B$2:B$406) -> -0.047304199 | C14: =CORREL(Data!F$2:F$406,Data!C$2:C$406) -> 0.38458338 | D14: =CORREL(Data!F$2:F$406,Data!D$2:D$406) -> 0.9589669 | E14: =CORREL(Data!F$2:F$406,Data!E$2:E$406) -> 0.16311141 | F14: =CORREL(Data!F$2:F$406,Data!F$2:F$406) -> 1 | G14: =CORREL(Data!F$2:F$406,Data!G$2:G$406) -> 0.26614468 | H14: =CORREL(Data!F$2:F$406,Data!H$2:H$406) -> 0.1095579 | I14: =CORREL(Data!F$2:F$406,Data!I$2:I$406) -> 0.11630826 | J14: =CORREL(Data!F$2:F$406,Data!J$2:J$406) -> 0.11353066 | K14: =CORREL(Data!F$2:F$406,Data!K$2:K$406) -> -0.013493642 | L14: =CORREL(Data!F$2:F$406,Data!L$2:L$406) -> 0.29752466 | M14: =CORREL(Data!F$2:F$406,Data!M$2:M$406) -> 0.2814719 | N14: =CORREL(Data!F$2:F$406,Data!N$2:N$406) -> 0.30446687
A15: x17 Attractive interior | B15: =CORREL(Data!G$2:G$406,Data!B$2:B$406) -> -0.11309748 | C15: =CORREL(Data!G$2:G$406,Data!C$2:C$406) -> 0.6717471 | D15: =CORREL(Data!G$2:G$406,Data!D$2:D$406) -> 0.28555402 | E15: =CORREL(Data!G$2:G$406,Data!E$2:E$406) -> -0.00031605663 | F15: =CORREL(Data!G$2:G$406,Data!F$2:F$406) -> 0.26614468 | G15: =CORREL(Data!G$2:G$406,Data!G$2:G$406) -> 1 | H15: =CORREL(Data!G$2:G$406,Data!H$2:H$406) -> -0.082293256 | I15: =CORREL(Data!G$2:G$406,Data!I$2:I$406) -> 0.080079197 | J15: =CORREL(Data!G$2:G$406,Data!J$2:J$406) -> 0.19004155 | K15: =CORREL(Data!G$2:G$406,Data!K$2:K$406) -> -0.064549624 | L15: =CORREL(Data!G$2:G$406,Data!L$2:L$406) -> 0.19555342 | M15: =CORREL(Data!G$2:G$406,Data!M$2:M$406) -> 0.27290607 | N15: =CORREL(Data!G$2:G$406,Data!N$2:N$406) -> 0.24839369
A16: x18 Excellent food taste | B16: =CORREL(Data!H$2:H$406,Data!B$2:B$406) -> 0.35558865 | C16: =CORREL(Data!H$2:H$406,Data!C$2:C$406) -> 0.029479771 | D16: =CORREL(Data!H$2:H$406,Data!D$2:D$406) -> 0.039537901 | E16: =CORREL(Data!H$2:H$406,Data!E$2:E$406) -> 0.78863234 | F16: =CORREL(Data!H$2:H$406,Data!F$2:F$406) -> 0.1095579 | G16: =CORREL(Data!H$2:H$406,Data!G$2:G$406) -> -0.082293256 | H16: =CORREL(Data!H$2:H$406,Data!H$2:H$406) -> 1 | I16: =CORREL(Data!H$2:H$406,Data!I$2:I$406) -> 0.3811817 | J16: =CORREL(Data!H$2:H$406,Data!J$2:J$406) -> 0.58855731 | K16: =CORREL(Data!H$2:H$406,Data!K$2:K$406) -> 0.16189496 | L16: =CORREL(Data!H$2:H$406,Data!L$2:L$406) -> 0.43992026 | M16: =CORREL(Data!H$2:H$406,Data!M$2:M$406) -> 0.45383321 | N16: =CORREL(Data!H$2:H$406,Data!N$2:N$406) -> 0.37161845
A17: x19 Knowledgeable employees | B17: =CORREL(Data!I$2:I$406,Data!B$2:B$406) -> 0.60103012 | C17: =CORREL(Data!I$2:I$406,Data!C$2:C$406) -> 0.12081759 | D17: =CORREL(Data!I$2:I$406,Data!D$2:D$406) -> 0.086387742 | E17: =CORREL(Data!I$2:I$406,Data!E$2:E$406) -> 0.39181483 | F17: =CORREL(Data!I$2:I$406,Data!F$2:F$406) -> 0.11630826 | G17: =CORREL(Data!I$2:I$406,Data!G$2:G$406) -> 0.080079197 | H17: =CORREL(Data!I$2:I$406,Data!H$2:H$406) -> 0.3811817 | I17: =CORREL(Data!I$2:I$406,Data!I$2:I$406) -> 1 | J17: =CORREL(Data!I$2:I$406,Data!J$2:J$406) -> 0.18542447 | K17: =CORREL(Data!I$2:I$406,Data!K$2:K$406) -> 0.50410278 | L17: =CORREL(Data!I$2:I$406,Data!L$2:L$406) -> 0.39701911 | M17: =CORREL(Data!I$2:I$406,Data!M$2:M$406) -> 0.44613226 | N17: =CORREL(Data!I$2:I$406,Data!N$2:N$406) -> 0.3350017
A18: x20 Proper food temperature | B18: =CORREL(Data!J$2:J$406,Data!B$2:B$406) -> 0.020013779 | C18: =CORREL(Data!J$2:J$406,Data!C$2:C$406) -> 0.090836075 | D18: =CORREL(Data!J$2:J$406,Data!D$2:D$406) -> 0.080364128 | E18: =CORREL(Data!J$2:J$406,Data!E$2:E$406) -> 0.50223431 | F18: =CORREL(Data!J$2:J$406,Data!F$2:F$406) -> 0.11353066 | G18: =CORREL(Data!J$2:J$406,Data!G$2:G$406) -> 0.19004155 | H18: =CORREL(Data!J$2:J$406,Data!H$2:H$406) -> 0.58855731 | I18: =CORREL(Data!J$2:J$406,Data!I$2:I$406) -> 0.18542447 | J18: =CORREL(Data!J$2:J$406,Data!J$2:J$406) -> 1 | K18: =CORREL(Data!J$2:J$406,Data!K$2:K$406) -> 0.043149929 | L18: =CORREL(Data!J$2:J$406,Data!L$2:L$406) -> 0.50435673 | M18: =CORREL(Data!J$2:J$406,Data!M$2:M$406) -> 0.51738352 | N18: =CORREL(Data!J$2:J$406,Data!N$2:N$406) -> 0.50495321
A19: x21 Quick service | B19: =CORREL(Data!K$2:K$406,Data!B$2:B$406) -> 0.81048299 | C19: =CORREL(Data!K$2:K$406,Data!C$2:C$406) -> -0.053638604 | D19: =CORREL(Data!K$2:K$406,Data!D$2:D$406) -> 0.017220084 | E19: =CORREL(Data!K$2:K$406,Data!E$2:E$406) -> 0.11492684 | F19: =CORREL(Data!K$2:K$406,Data!F$2:F$406) -> -0.013493642 | G19: =CORREL(Data!K$2:K$406,Data!G$2:G$406) -> -0.064549624 | H19: =CORREL(Data!K$2:K$406,Data!H$2:H$406) -> 0.16189496 | I19: =CORREL(Data!K$2:K$406,Data!I$2:I$406) -> 0.50410278 | J19: =CORREL(Data!K$2:K$406,Data!J$2:J$406) -> 0.043149929 | K19: =CORREL(Data!K$2:K$406,Data!K$2:K$406) -> 1 | L19: =CORREL(Data!K$2:K$406,Data!L$2:L$406) -> 0.38376891 | M19: =CORREL(Data!K$2:K$406,Data!M$2:M$406) -> 0.32381579 | N19: =CORREL(Data!K$2:K$406,Data!N$2:N$406) -> 0.1633609
A20: x22 Satisfaction | B20: =CORREL(Data!L$2:L$406,Data!B$2:B$406) -> 0.42466259 | C20: =CORREL(Data!L$2:L$406,Data!C$2:C$406) -> 0.21909641 | D20: =CORREL(Data!L$2:L$406,Data!D$2:D$406) -> 0.30797615 | E20: =CORREL(Data!L$2:L$406,Data!E$2:E$406) -> 0.55855337 | F20: =CORREL(Data!L$2:L$406,Data!F$2:F$406) -> 0.29752466 | G20: =CORREL(Data!L$2:L$406,Data!G$2:G$406) -> 0.19555342 | H20: =CORREL(Data!L$2:L$406,Data!H$2:H$406) -> 0.43992026 | I20: =CORREL(Data!L$2:L$406,Data!I$2:I$406) -> 0.39701911 | J20: =CORREL(Data!L$2:L$406,Data!J$2:J$406) -> 0.50435673 | K20: =CORREL(Data!L$2:L$406,Data!K$2:K$406) -> 0.38376891 | L20: =CORREL(Data!L$2:L$406,Data!L$2:L$406) -> 1 | M20: =CORREL(Data!L$2:L$406,Data!M$2:M$406) -> 0.82379182 | N20: =CORREL(Data!L$2:L$406,Data!N$2:N$406) -> 0.80183752
A21: x23 Likely to return | B21: =CORREL(Data!M$2:M$406,Data!B$2:B$406) -> 0.36082335 | C21: =CORREL(Data!M$2:M$406,Data!C$2:C$406) -> 0.22502167 | D21: =CORREL(Data!M$2:M$406,Data!D$2:D$406) -> 0.26829056 | E21: =CORREL(Data!M$2:M$406,Data!E$2:E$406) -> 0.49607151 | F21: =CORREL(Data!M$2:M$406,Data!F$2:F$406) -> 0.2814719 | G21: =CORREL(Data!M$2:M$406,Data!G$2:G$406) -> 0.27290607 | H21: =CORREL(Data!M$2:M$406,Data!H$2:H$406) -> 0.45383321 | I21: =CORREL(Data!M$2:M$406,Data!I$2:I$406) -> 0.44613226 | J21: =CORREL(Data!M$2:M$406,Data!J$2:J$406) -> 0.51738352 | K21: =CORREL(Data!M$2:M$406,Data!K$2:K$406) -> 0.32381579 | L21: =CORREL(Data!M$2:M$406,Data!L$2:L$406) -> 0.82379182 | M21: =CORREL(Data!M$2:M$406,Data!M$2:M$406) -> 1 | N21: =CORREL(Data!M$2:M$406,Data!N$2:N$406) -> 0.84413513
A22: x24 Likely to recommend | B22: =CORREL(Data!N$2:N$406,Data!B$2:B$406) -> 0.19056756 | C22: =CORREL(Data!N$2:N$406,Data!C$2:C$406) -> 0.27367444 | D22: =CORREL(Data!N$2:N$406,Data!D$2:D$406) -> 0.30790267 | E22: =CORREL(Data!N$2:N$406,Data!E$2:E$406) -> 0.47061021 | F22: =CORREL(Data!N$2:N$406,Data!F$2:F$406) -> 0.30446687 | G22: =CORREL(Data!N$2:N$406,Data!G$2:G$406) -> 0.24839369 | H22: =CORREL(Data!N$2:N$406,Data!H$2:H$406) -> 0.37161845 | I22: =CORREL(Data!N$2:N$406,Data!I$2:I$406) -> 0.3350017 | J22: =CORREL(Data!N$2:N$406,Data!J$2:J$406) -> 0.50495321 | K22: =CORREL(Data!N$2:N$406,Data!K$2:K$406) -> 0.1633609 | L22: =CORREL(Data!N$2:N$406,Data!L$2:L$406) -> 0.80183752 | M22: =CORREL(Data!N$2:N$406,Data!M$2:M$406) -> 0.84413513 | N22: =CORREL(Data!N$2:N$406,Data!N$2:N$406) -> 1
A23: Color: blue = positive, red = negative, grey = near zero. Diagonal = 1 (an item with itself).
A25: Indicator | B25: Question | C25: r with x22 | D25: p | E25: Strength | F25: r with x23 | G25: p | H25: Strength | I25: r with x24 | J25: p | K25: Strength
A26: x12 | B26: Friendly employees | C26: =L10 -> 0.42466259 | D26: =_xlfn.T.DIST.2T(ABS(C26)*SQRT($B$5/(1-C26^2)),$B$5) -> 3.6610721e-19 | E26: =IF(ABS(C26)<0.1,"negligible",IF(ABS(C26)<0.3,"weak",IF(ABS(C26)<0.5,"moderate",IF(ABS(C26)<0.7,"strong","very strong")))) -> moderate | F26: =M10 -> 0.36082335 | G26: =_xlfn.T.DIST.2T(ABS(F26)*SQRT($B$5/(1-F26^2)),$B$5) -> 6.7374621e-14 | H26: =IF(ABS(F26)<0.1,"negligible",IF(ABS(F26)<0.3,"weak",IF(ABS(F26)<0.5,"moderate",IF(ABS(F26)<0.7,"strong","very strong")))) -> moderate | I26: =N10 -> 0.19056756 | J26: =_xlfn.T.DIST.2T(ABS(I26)*SQRT($B$5/(1-I26^2)),$B$5) -> 0.00011400889 | K26: =IF(ABS(I26)<0.1,"negligible",IF(ABS(I26)<0.3,"weak",IF(ABS(I26)<0.5,"moderate",IF(ABS(I26)<0.7,"strong","very strong")))) -> weak
A27: x13 | B27: Fun place to eat | C27: =L11 -> 0.21909641 | D27: =_xlfn.T.DIST.2T(ABS(C27)*SQRT($B$5/(1-C27^2)),$B$5) -> 8.5957556e-06 | E27: =IF(ABS(C27)<0.1,"negligible",IF(ABS(C27)<0.3,"weak",IF(ABS(C27)<0.5,"moderate",IF(ABS(C27)<0.7,"strong","very strong")))) -> weak | F27: =M11 -> 0.22502167 | G27: =_xlfn.T.DIST.2T(ABS(F27)*SQRT($B$5/(1-F27^2)),$B$5) -> 4.8019451e-06 | H27: =IF(ABS(F27)<0.1,"negligible",IF(ABS(F27)<0.3,"weak",IF(ABS(F27)<0.5,"moderate",IF(ABS(F27)<0.7,"strong","very strong")))) -> weak | I27: =N11 -> 0.27367444 | J27: =_xlfn.T.DIST.2T(ABS(I27)*SQRT($B$5/(1-I27^2)),$B$5) -> 2.170978e-08 | K27: =IF(ABS(I27)<0.1,"negligible",IF(ABS(I27)<0.3,"weak",IF(ABS(I27)<0.5,"moderate",IF(ABS(I27)<0.7,"strong","very strong")))) -> weak
A28: x14 | B28: Large portions | C28: =L12 -> 0.30797615 | D28: =_xlfn.T.DIST.2T(ABS(C28)*SQRT($B$5/(1-C28^2)),$B$5) -> 2.3991992e-10 | E28: =IF(ABS(C28)<0.1,"negligible",IF(ABS(C28)<0.3,"weak",IF(ABS(C28)<0.5,"moderate",IF(ABS(C28)<0.7,"strong","very strong")))) -> moderate | F28: =M12 -> 0.26829056 | G28: =_xlfn.T.DIST.2T(ABS(F28)*SQRT($B$5/(1-F28^2)),$B$5) -> 4.1721568e-08 | H28: =IF(ABS(F28)<0.1,"negligible",IF(ABS(F28)<0.3,"weak",IF(ABS(F28)<0.5,"moderate",IF(ABS(F28)<0.7,"strong","very strong")))) -> weak | I28: =N12 -> 0.30790267 | J28: =_xlfn.T.DIST.2T(ABS(I28)*SQRT($B$5/(1-I28^2)),$B$5) -> 2.4240428e-10 | K28: =IF(ABS(I28)<0.1,"negligible",IF(ABS(I28)<0.3,"weak",IF(ABS(I28)<0.5,"moderate",IF(ABS(I28)<0.7,"strong","very strong")))) -> moderate
A29: x15 | B29: Fresh food | C29: =L13 -> 0.55855337 | D29: =_xlfn.T.DIST.2T(ABS(C29)*SQRT($B$5/(1-C29^2)),$B$5) -> 1.3365845e-34 | E29: =IF(ABS(C29)<0.1,"negligible",IF(ABS(C29)<0.3,"weak",IF(ABS(C29)<0.5,"moderate",IF(ABS(C29)<0.7,"strong","very strong")))) -> strong | F29: =M13 -> 0.49607151 | G29: =_xlfn.T.DIST.2T(ABS(F29)*SQRT($B$5/(1-F29^2)),$B$5) -> 1.5152478e-26 | H29: =IF(ABS(F29)<0.1,"negligible",IF(ABS(F29)<0.3,"weak",IF(ABS(F29)<0.5,"moderate",IF(ABS(F29)<0.7,"strong","very strong")))) -> moderate | I29: =N13 -> 0.47061021 | J29: =_xlfn.T.DIST.2T(ABS(I29)*SQRT($B$5/(1-I29^2)),$B$5) -> 1.0332425e-23 | K29: =IF(ABS(I29)<0.1,"negligible",IF(ABS(I29)<0.3,"weak",IF(ABS(I29)<0.5,"moderate",IF(ABS(I29)<0.7,"strong","very strong")))) -> moderate
A30: x16 | B30: Reasonable prices | C30: =L14 -> 0.29752466 | D30: =_xlfn.T.DIST.2T(ABS(C30)*SQRT($B$5/(1-C30^2)),$B$5) -> 1.0093418e-09 | E30: =IF(ABS(C30)<0.1,"negligible",IF(ABS(C30)<0.3,"weak",IF(ABS(C30)<0.5,"moderate",IF(ABS(C30)<0.7,"strong","very strong")))) -> weak | F30: =M14 -> 0.2814719 | G30: =_xlfn.T.DIST.2T(ABS(F30)*SQRT($B$5/(1-F30^2)),$B$5) -> 8.2168095e-09 | H30: =IF(ABS(F30)<0.1,"negligible",IF(ABS(F30)<0.3,"weak",IF(ABS(F30)<0.5,"moderate",IF(ABS(F30)<0.7,"strong","very strong")))) -> weak | I30: =N14 -> 0.30446687 | J30: =_xlfn.T.DIST.2T(ABS(I30)*SQRT($B$5/(1-I30^2)),$B$5) -> 3.9115644e-10 | K30: =IF(ABS(I30)<0.1,"negligible",IF(ABS(I30)<0.3,"weak",IF(ABS(I30)<0.5,"moderate",IF(ABS(I30)<0.7,"strong","very strong")))) -> moderate
A31: x17 | B31: Attractive interior | C31: =L15 -> 0.19555342 | D31: =_xlfn.T.DIST.2T(ABS(C31)*SQRT($B$5/(1-C31^2)),$B$5) -> 7.4453544e-05 | E31: =IF(ABS(C31)<0.1,"negligible",IF(ABS(C31)<0.3,"weak",IF(ABS(C31)<0.5,"moderate",IF(ABS(C31)<0.7,"strong","very strong")))) -> weak | F31: =M15 -> 0.27290607 | G31: =_xlfn.T.DIST.2T(ABS(F31)*SQRT($B$5/(1-F31^2)),$B$5) -> 2.3851999e-08 | H31: =IF(ABS(F31)<0.1,"negligible",IF(ABS(F31)<0.3,"weak",IF(ABS(F31)<0.5,"moderate",IF(ABS(F31)<0.7,"strong","very strong")))) -> weak | I31: =N15 -> 0.24839369 | J31: =_xlfn.T.DIST.2T(ABS(I31)*SQRT($B$5/(1-I31^2)),$B$5) -> 4.1283647e-07 | K31: =IF(ABS(I31)<0.1,"negligible",IF(ABS(I31)<0.3,"weak",IF(ABS(I31)<0.5,"moderate",IF(ABS(I31)<0.7,"strong","very strong")))) -> weak
A32: x18 | B32: Excellent food taste | C32: =L16 -> 0.43992026 | D32: =_xlfn.T.DIST.2T(ABS(C32)*SQRT($B$5/(1-C32^2)),$B$5) -> 1.3453272e-20 | E32: =IF(ABS(C32)<0.1,"negligible",IF(ABS(C32)<0.3,"weak",IF(ABS(C32)<0.5,"moderate",IF(ABS(C32)<0.7,"strong","very strong")))) -> moderate | F32: =M16 -> 0.45383321 | G32: =_xlfn.T.DIST.2T(ABS(F32)*SQRT($B$5/(1-F32^2)),$B$5) -> 5.6992325e-22 | H32: =IF(ABS(F32)<0.1,"negligible",IF(ABS(F32)<0.3,"weak",IF(ABS(F32)<0.5,"moderate",IF(ABS(F32)<0.7,"strong","very strong")))) -> moderate | I32: =N16 -> 0.37161845 | J32: =_xlfn.T.DIST.2T(ABS(I32)*SQRT($B$5/(1-I32^2)),$B$5) -> 1.039923e-14 | K32: =IF(ABS(I32)<0.1,"negligible",IF(ABS(I32)<0.3,"weak",IF(ABS(I32)<0.5,"moderate",IF(ABS(I32)<0.7,"strong","very strong")))) -> moderate
A33: x19 | B33: Knowledgeable employees | C33: =L17 -> 0.39701911 | D33: =_xlfn.T.DIST.2T(ABS(C33)*SQRT($B$5/(1-C33^2)),$B$5) -> 9.6403042e-17 | E33: =IF(ABS(C33)<0.1,"negligible",IF(ABS(C33)<0.3,"weak",IF(ABS(C33)<0.5,"moderate",IF(ABS(C33)<0.7,"strong","very strong")))) -> moderate | F33: =M17 -> 0.44613226 | G33: =_xlfn.T.DIST.2T(ABS(F33)*SQRT($B$5/(1-F33^2)),$B$5) -> 3.3387147e-21 | H33: =IF(ABS(F33)<0.1,"negligible",IF(ABS(F33)<0.3,"weak",IF(ABS(F33)<0.5,"moderate",IF(ABS(F33)<0.7,"strong","very strong")))) -> moderate | I33: =N17 -> 0.3350017 | J33: =_xlfn.T.DIST.2T(ABS(I33)*SQRT($B$5/(1-I33^2)),$B$5) -> 4.4544065e-12 | K33: =IF(ABS(I33)<0.1,"negligible",IF(ABS(I33)<0.3,"weak",IF(ABS(I33)<0.5,"moderate",IF(ABS(I33)<0.7,"strong","very strong")))) -> moderate
A34: x20 | B34: Proper food temperature | C34: =L18 -> 0.50435673 | D34: =_xlfn.T.DIST.2T(ABS(C34)*SQRT($B$5/(1-C34^2)),$B$5) -> 1.6068714e-27 | E34: =IF(ABS(C34)<0.1,"negligible",IF(ABS(C34)<0.3,"weak",IF(ABS(C34)<0.5,"moderate",IF(ABS(C34)<0.7,"strong","very strong")))) -> strong | F34: =M18 -> 0.51738352 | G34: =_xlfn.T.DIST.2T(ABS(F34)*SQRT($B$5/(1-F34^2)),$B$5) -> 4.1578427e-29 | H34: =IF(ABS(F34)<0.1,"negligible",IF(ABS(F34)<0.3,"weak",IF(ABS(F34)<0.5,"moderate",IF(ABS(F34)<0.7,"strong","very strong")))) -> strong | I34: =N18 -> 0.50495321 | J34: =_xlfn.T.DIST.2T(ABS(I34)*SQRT($B$5/(1-I34^2)),$B$5) -> 1.3639279e-27 | K34: =IF(ABS(I34)<0.1,"negligible",IF(ABS(I34)<0.3,"weak",IF(ABS(I34)<0.5,"moderate",IF(ABS(I34)<0.7,"strong","very strong")))) -> strong
A35: x21 | B35: Quick service | C35: =L19 -> 0.38376891 | D35: =_xlfn.T.DIST.2T(ABS(C35)*SQRT($B$5/(1-C35^2)),$B$5) -> 1.1657136e-15 | E35: =IF(ABS(C35)<0.1,"negligible",IF(ABS(C35)<0.3,"weak",IF(ABS(C35)<0.5,"moderate",IF(ABS(C35)<0.7,"strong","very strong")))) -> moderate | F35: =M19 -> 0.32381579 | G35: =_xlfn.T.DIST.2T(ABS(F35)*SQRT($B$5/(1-F35^2)),$B$5) -> 2.4342052e-11 | H35: =IF(ABS(F35)<0.1,"negligible",IF(ABS(F35)<0.3,"weak",IF(ABS(F35)<0.5,"moderate",IF(ABS(F35)<0.7,"strong","very strong")))) -> moderate | I35: =N19 -> 0.1633609 | J35: =_xlfn.T.DIST.2T(ABS(I35)*SQRT($B$5/(1-I35^2)),$B$5) -> 0.00096820729 | K35: =IF(ABS(I35)<0.1,"negligible",IF(ABS(I35)<0.3,"weak",IF(ABS(I35)<0.5,"moderate",IF(ABS(I35)<0.7,"strong","very strong")))) -> weak
A37: Significant at alpha (out of 30) | C37: =COUNTIF(D26:D35,"<"&$B$4)+COUNTIF(G26:G35,"<"&$B$4)+COUNTIF(J26:J35,"<"&$B$4) -> 30
A38: Strength labels (rule of thumb): below 0.10 negligible, 0.10 to 0.29 weak, 0.30 to 0.49 moderate, 0.50 to 0.69 strong, 0.70 and up very strong.
A39: Spearman (rank) correlations, a robustness check, are in the notebook; they never differ from Pearson by more than 0.07.

Sheet ANOVA Data
A1: id | B1: x15 freshness (group) | C1: x22 satisfaction | D1: Group mean of x22 | E1: Squared deviation from group mean | F1: |Deviation| (for Levene) | G1: Rank of x22 (for Kruskal-Wallis)
A2: 8 | B2: 4 | C2: 4 | D2: =AVERAGEIF($B$2:$B$406,B2,$C$2:$C$406) -> 3.9882353 | E2: =(C2-D2)^2 -> 0.0001384083 | F2: =ABS(C2-D2) -> 0.011764706 | G2: =_xlfn.RANK.AVG(C2,$C$2:$C$406,1) -> 112.5 | I2: Columns A to C are copied from the Data sheet and sorted by freshness, then id.
A3: 12 | B3: 4 | C3: 4 | D3: =AVERAGEIF($B$2:$B$406,B3,$C$2:$C$406) -> 3.9882353 | E3: =(C3-D3)^2 -> 0.0001384083 | F3: =ABS(C3-D3) -> 0.011764706 | G3: =_xlfn.RANK.AVG(C3,$C$2:$C$406,1) -> 112.5 | I3: Ties get the average rank (RANK.AVG), as Kruskal-Wallis requires.
A4: 13 | B4: 4 | C4: 6 | D4: =AVERAGEIF($B$2:$B$406,B4,$C$2:$C$406) -> 3.9882353 | E4: =(C4-D4)^2 -> 4.0471972 | F4: =ABS(C4-D4) -> 2.0117647 | G4: =_xlfn.RANK.AVG(C4,$C$2:$C$406,1) -> 328
A5: 17 | B5: 4 | C5: 4 | D5: =AVERAGEIF($B$2:$B$406,B5,$C$2:$C$406) -> 3.9882353 | E5: =(C5-D5)^2 -> 0.0001384083 | F5: =ABS(C5-D5) -> 0.011764706 | G5: =_xlfn.RANK.AVG(C5,$C$2:$C$406,1) -> 112.5
A6: 18 | B6: 4 | C6: 4 | D6: =AVERAGEIF($B$2:$B$406,B6,$C$2:$C$406) -> 3.9882353 | E6: =(C6-D6)^2 -> 0.0001384083 | F6: =ABS(C6-D6) -> 0.011764706 | G6: =_xlfn.RANK.AVG(C6,$C$2:$C$406,1) -> 112.5
A7: 21 | B7: 4 | C7: 4 | D7: =AVERAGEIF($B$2:$B$406,B7,$C$2:$C$406) -> 3.9882353 | E7: =(C7-D7)^2 -> 0.0001384083 | F7: =ABS(C7-D7) -> 0.011764706 | G7: =_xlfn.RANK.AVG(C7,$C$2:$C$406,1) -> 112.5
A8: 22 | B8: 4 | C8: 4 | D8: =AVERAGEIF($B$2:$B$406,B8,$C$2:$C$406) -> 3.9882353 | E8: =(C8-D8)^2 -> 0.0001384083 | F8: =ABS(C8-D8) -> 0.011764706 | G8: =_xlfn.RANK.AVG(C8,$C$2:$C$406,1) -> 112.5
A9: 24 | B9: 4 | C9: 3 | D9: =AVERAGEIF($B$2:$B$406,B9,$C$2:$C$406) -> 3.9882353 | E9: =(C9-D9)^2 -> 0.976609 | F9: =ABS(C9-D9) -> 0.98823529 | G9: =_xlfn.RANK.AVG(C9,$C$2:$C$406,1) -> 19.5
A10: 50 | B10: 4 | C10: 4 | D10: =AVERAGEIF($B$2:$B$406,B10,$C$2:$C$406) -> 3.9882353 | E10: =(C10-D10)^2 -> 0.0001384083 | F10: =ABS(C10-D10) -> 0.011764706 | G10: =_xlfn.RANK.AVG(C10,$C$2:$C$406,1) -> 112.5
A11: 52 | B11: 4 | C11: 4 | D11: =AVERAGEIF($B$2:$B$406,B11,$C$2:$C$406) -> 3.9882353 | E11: =(C11-D11)^2 -> 0.0001384083 | F11: =ABS(C11-D11) -> 0.011764706 | G11: =_xlfn.RANK.AVG(C11,$C$2:$C$406,1) -> 112.5
A12: 54 | B12: 4 | C12: 4 | D12: =AVERAGEIF($B$2:$B$406,B12,$C$2:$C$406) -> 3.9882353 | E12: =(C12-D12)^2 -> 0.0001384083 | F12: =ABS(C12-D12) -> 0.011764706 | G12: =_xlfn.RANK.AVG(C12,$C$2:$C$406,1) -> 112.5
A13: 56 | B13: 4 | C13: 4 | D13: =AVERAGEIF($B$2:$B$406,B13,$C$2:$C$406) -> 3.9882353 | E13: =(C13-D13)^2 -> 0.0001384083 | F13: =ABS(C13-D13) -> 0.011764706 | G13: =_xlfn.RANK.AVG(C13,$C$2:$C$406,1) -> 112.5
A14: 58 | B14: 4 | C14: 3 | D14: =AVERAGEIF($B$2:$B$406,B14,$C$2:$C$406) -> 3.9882353 | E14: =(C14-D14)^2 -> 0.976609 | F14: =ABS(C14-D14) -> 0.98823529 | G14: =_xlfn.RANK.AVG(C14,$C$2:$C$406,1) -> 19.5
A15: 71 | B15: 4 | C15: 4 | D15: =AVERAGEIF($B$2:$B$406,B15,$C$2:$C$406) -> 3.9882353 | E15: =(C15-D15)^2 -> 0.0001384083 | F15: =ABS(C15-D15) -> 0.011764706 | G15: =_xlfn.RANK.AVG(C15,$C$2:$C$406,1) -> 112.5
... A406: 403 | B406: 7 | C406: 6 | D406: =AVERAGEIF($B$2:$B$406,B406,$C$2:$C$406) -> 5.5149701 | E406: =(C406-D406)^2 -> 0.23525404 | F406: =ABS(C406-D406) -> 0.48502994 | G406: =_xlfn.RANK.AVG(C406,$C$2:$C$406,1) -> 328

Sheet ANOVA
A1: Part B. One-Way ANOVA: Satisfaction (x22) Across Freshness Levels (x15)
A2: Research question: does customer satisfaction differ across levels of perceived food freshness? H0: mean satisfaction is equal at every freshness level. H1: at least one level differs.
A4: Alpha | B4: =Correlation!B4 -> 0.05
A5: Number of groups (k) | B5: =COUNT(A9:A12) -> 4
A8: Freshness level | B8: n | C8: Mean x22 | D8: SD | E8: Variance | F8: Sum of ranks | G8: Mean |dev| | H8: SS within | I8: Welch weight n/var | J8: Welch lambda term
A9: 4 | B9: =COUNTIF('ANOVA Data'!$B$2:$B$406,A9) -> 85 | C9: =AVERAGEIF('ANOVA Data'!$B$2:$B$406,A9,'ANOVA Data'!$C$2:$C$406) -> 3.9882353 | D9: =SQRT(E9) -> 0.58745046 | E9: =H9/(B9-1) -> 0.34509804 | F9: =SUMIF('ANOVA Data'!$B$2:$B$406,A9,'ANOVA Data'!$G$2:$G$406) -> 9644.5 | G9: =AVERAGEIF('ANOVA Data'!$B$2:$B$406,A9,'ANOVA Data'!$F$2:$F$406) -> 0.25577855 | H9: =SUMIF('ANOVA Data'!$B$2:$B$406,A9,'ANOVA Data'!$E$2:$E$406) -> 28.988235 | I9: =B9/E9 -> 246.30682 | J9: =(1-I9/SUM($I$9:$I$12))^2/(B9-1) -> 0.0042001621
A10: 5 | B10: =COUNTIF('ANOVA Data'!$B$2:$B$406,A10) -> 93 | C10: =AVERAGEIF('ANOVA Data'!$B$2:$B$406,A10,'ANOVA Data'!$C$2:$C$406) -> 4.3548387 | D10: =SQRT(E10) -> 0.77523014 | E10: =H10/(B10-1) -> 0.60098177 | F10: =SUMIF('ANOVA Data'!$B$2:$B$406,A10,'ANOVA Data'!$G$2:$G$406) -> 14844.5 | G10: =AVERAGEIF('ANOVA Data'!$B$2:$B$406,A10,'ANOVA Data'!$F$2:$F$406) -> 0.68123482 | H10: =SUMIF('ANOVA Data'!$B$2:$B$406,A10,'ANOVA Data'!$E$2:$E$406) -> 55.290323 | I10: =B10/E10 -> 154.74679 | J10: =(1-I10/SUM($I$9:$I$12))^2/(B10-1) -> 0.0060314422
A11: 6 | B11: =COUNTIF('ANOVA Data'!$B$2:$B$406,A11) -> 60 | C11: =AVERAGEIF('ANOVA Data'!$B$2:$B$406,A11,'ANOVA Data'!$C$2:$C$406) -> 4.85 | D11: =SQRT(E11) -> 1.286501 | E11: =H11/(B11-1) -> 1.6550847 | F11: =SUMIF('ANOVA Data'!$B$2:$B$406,A11,'ANOVA Data'!$G$2:$G$406) -> 12354 | G11: =AVERAGEIF('ANOVA Data'!$B$2:$B$406,A11,'ANOVA Data'!$F$2:$F$406) -> 1.08 | H11: =SUMIF('ANOVA Data'!$B$2:$B$406,A11,'ANOVA Data'!$E$2:$E$406) -> 97.65 | I11: =B11/E11 -> 36.25192 | J11: =(1-I11/SUM($I$9:$I$12))^2/(B11-1) -> 0.014983963
A12: 7 | B12: =COUNTIF('ANOVA Data'!$B$2:$B$406,A12) -> 167 | C12: =AVERAGEIF('ANOVA Data'!$B$2:$B$406,A12,'ANOVA Data'!$C$2:$C$406) -> 5.5149701 | D12: =SQRT(E12) -> 0.99308627 | E12: =H12/(B12-1) -> 0.98622033 | F12: =SUMIF('ANOVA Data'!$B$2:$B$406,A12,'ANOVA Data'!$G$2:$G$406) -> 45372 | G12: =AVERAGEIF('ANOVA Data'!$B$2:$B$406,A12,'ANOVA Data'!$F$2:$F$406) -> 0.86284915 | H12: =SUMIF('ANOVA Data'!$B$2:$B$406,A12,'ANOVA Data'!$E$2:$E$406) -> 163.71257 | I12: =B12/E12 -> 169.33336 | J12: =(1-I12/SUM($I$9:$I$12))^2/(B12-1) -> 0.003130411
A13: All | B13: =SUM(B9:B12) -> 405 | C13: =AVERAGE('ANOVA Data'!C2:C406) -> 4.8296296
A15: Largest SD / smallest SD | B15: =MAX(D9:D12)/MIN(D9:D12) -> 2.1899736
A17: Levene's test (mean-centered): one-way ANOVA on |x22 - group mean|
A18: Grand mean of |dev| | B18: =AVERAGE('ANOVA Data'!F2:F406) -> 0.72590574
A19: SS between (|dev|) | B19: =SUMPRODUCT(B9:B12,(G9:G12-B18)^2) -> 29.627044
A20: SS within (|dev|) | B20: =DEVSQ('ANOVA Data'!F2:F406)-B19 -> 102.60374
A21: Levene F | B21: =(B19/(B5-1))/(B20/(B13-B5)) -> 38.596529
A22: p-value | B22: =_xlfn.F.DIST.RT(B21,B5-1,B13-B5) -> 6.2262303e-22
A23: Equal variances? | B23: =IF(B22<B4,"No: variances differ (assumption violated)","Yes") -> No: variances differ (assumption violated)
A25: One-way ANOVA table
A26: Source | B26: SS | C26: df | D26: MS | E26: F | F26: p-value | G26: F critical
A27: Between groups (freshness) | B27: =SUMPRODUCT(B9:B12,(C9:C12-C13)^2) -> 159.60331 | C27: =B5-1 -> 3 | D27: =B27/C27 -> 53.201104 | E27: =D27/D28 -> 61.721944 | F27: =_xlfn.F.DIST.RT(E27,C27,C28) -> 7.920365e-33 | G27: =_xlfn.F.INV.RT(B4,C27,C28) -> 2.6271584
A28: Within groups (error) | B28: =SUM(H9:H12) -> 345.64113 | C28: =B13-B5 -> 401 | D28: =B28/C28 -> 0.86194796
A29: Total | B29: =DEVSQ('ANOVA Data'!C2:C406) -> 505.24444 | C29: =B13-1 -> 404
A30: Check: SS between + SS within - SS total (should be 0) | B30: =B27+B28-B29 -> -6.8212103e-13
A31: Effect size: eta squared = SS between / SS total | B31: =B27/B29 -> 0.31589325
A32: Decision at alpha | B32: =IF(F27<B4,"Reject H0: mean satisfaction differs across freshness levels","Fail to reject H0") -> Reject H0: mean satisfaction differs across freshness levels
A34: Remedy 1. Welch's ANOVA (does not assume equal variances)
A35: Weighted grand mean | B35: =SUMPRODUCT(I9:I12,C9:C12)/SUM(I9:I12) -> 4.5594127
A36: Between term A | B36: =SUMPRODUCT(I9:I12,(C9:C12-B35)^2)/(B5-1) -> 81.503328
A37: Lambda | B37: =SUM(J9:J12) -> 0.028345978
A38: Welch F | B38: =B36/(1+2*(B5-2)/(B5^2-1)*B37) -> 80.891872
A39: df1 | B39: =B5-1 -> 3
A40: df2 | B40: =(B5^2-1)/(3*B37) -> 176.39187
A41: p-value | B41: =_xlfn.F.DIST.RT(B38,B39,B40) -> 6.1624459e-33 | C41: Excel's F.DIST.RT rounds df2 down to a whole number (176), so this p differs from Python's in the far decimal places; the decision is the same.
A43: Remedy 2. Kruskal-Wallis test (compares ranks; no normality or equal-variance assumption)
E44: x22 value | F44: Count (ties) | G44: t^3 - t
A45: H before tie correction | B45: =12/(B13*(B13+1))*SUMPRODUCT(F9:F12^2/B9:B12)-3*(B13+1) -> 120.04114 | E45: 1 | F45: =COUNTIF('ANOVA Data'!$C$2:$C$406,E45) -> 0 | G45: =F45^3-F45 -> 0
A46: Tie correction | B46: =1-SUM(G45:G51)/(B13^3-B13) -> 0.92491641 | E46: 2 | F46: =COUNTIF('ANOVA Data'!$C$2:$C$406,E46) -> 0 | G46: =F46^3-F46 -> 0
A47: H (corrected) | B47: =B45/B46 -> 129.78593 | E47: 3 | F47: =COUNTIF('ANOVA Data'!$C$2:$C$406,E47) -> 38 | G47: =F47^3-F47 -> 54834
A48: df | B48: =B5-1 -> 3 | E48: 4 | F48: =COUNTIF('ANOVA Data'!$C$2:$C$406,E48) -> 148 | G48: =F48^3-F48 -> 3241644
...

Sheet Charts
A1: Charts
L21: Perception (sorted) | M21: r with satisfaction
L22: =INDEX(Correlation!$B$26:$B$35,MATCH(M22,Correlation!$C$26:$C$35,0)) -> Attractive interior | M22: =SMALL(Correlation!$C$26:$C$35,1) -> 0.19555342
L23: =INDEX(Correlation!$B$26:$B$35,MATCH(M23,Correlation!$C$26:$C$35,0)) -> Fun place to eat | M23: =SMALL(Correlation!$C$26:$C$35,2) -> 0.21909641
L24: =INDEX(Correlation!$B$26:$B$35,MATCH(M24,Correlation!$C$26:$C$35,0)) -> Reasonable prices | M24: =SMALL(Correlation!$C$26:$C$35,3) -> 0.29752466
L25: =INDEX(Correlation!$B$26:$B$35,MATCH(M25,Correlation!$C$26:$C$35,0)) -> Large portions | M25: =SMALL(Correlation!$C$26:$C$35,4) -> 0.30797615
L26: =INDEX(Correlation!$B$26:$B$35,MATCH(M26,Correlation!$C$26:$C$35,0)) -> Quick service | M26: =SMALL(Correlation!$C$26:$C$35,5) -> 0.38376891
L27: =INDEX(Correlation!$B$26:$B$35,MATCH(M27,Correlation!$C$26:$C$35,0)) -> Knowledgeable employees | M27: =SMALL(Correlation!$C$26:$C$35,6) -> 0.39701911
L28: =INDEX(Correlation!$B$26:$B$35,MATCH(M28,Correlation!$C$26:$C$35,0)) -> Friendly employees | M28: =SMALL(Correlation!$C$26:$C$35,7) -> 0.42466259
L29: =INDEX(Correlation!$B$26:$B$35,MATCH(M29,Correlation!$C$26:$C$35,0)) -> Excellent food taste | M29: =SMALL(Correlation!$C$26:$C$35,8) -> 0.43992026
L30: =INDEX(Correlation!$B$26:$B$35,MATCH(M30,Correlation!$C$26:$C$35,0)) -> Proper food temperature | M30: =SMALL(Correlation!$C$26:$C$35,9) -> 0.50435673
L31: =INDEX(Correlation!$B$26:$B$35,MATCH(M31,Correlation!$C$26:$C$35,0)) -> Fresh food | M31: =SMALL(Correlation!$C$26:$C$35,10) -> 0.55855337
L33: Sorted with SMALL and INDEX/MATCH, so the chart updates if the data change.

Sheet Summary
A1: Key Results and How to Defend Them
A3: Result | B3: Value | C3: How to defend this
A4: Rows / missing / duplicate ids / impossible answers | B4: =Cleaning!B4&" / "&Cleaning!B5&" / "&Cleaning!B6&" / "&Cleaning!B7 -> 405 / 0 / 0 / 0 | C4: The data needed no removals or imputation; only the non-data columns with the task note were left out.
A5: Critical r at alpha 0.05 | B5: =Correlation!B7 -> 0.097460664 | C5: With 405 people, any |r| above this is significant, so judge correlations by their size, not their p-value.
A6: Strongest correlate of satisfaction: fresh food (r) | B6: =Correlation!C29 -> 0.55855337 | C6: Food quality (freshness, temperature, taste) is most closely tied to satisfaction; interior and atmosphere least.
A7: Correlations significant at alpha (out of 30) | B7: =Correlation!C37 -> 30 | C7: All are positive: every perception moves in the same direction as the outcomes.
A8: Levene F (p) | B8: =TEXT(ANOVA!B21,"0.00")&" (p = "&TEXT(ANOVA!B22,"0.0E+00")&")" -> 38.60 (p = 6.2E-22) | C8: Variances differ across groups (assumption violated), so Welch's ANOVA is used as a check.
A9: ANOVA F (df) | B9: =TEXT(ANOVA!E27,"0.00")&" (df = "&ANOVA!C27&", "&ANOVA!C28&")" -> 61.72 (df = 3, 401) | C9: F compares the spread between group means with the spread inside groups; this is far above F critical.
A10: ANOVA p-value | B10: =ANOVA!F27 -> 7.920365e-33 | C10: Far below 0.05, so reject H0: mean satisfaction differs across freshness levels.
A11: Eta squared | B11: =ANOVA!B31 -> 0.31589325 | C11: Freshness level explains about this share of the variation in satisfaction: a large effect (0.14 and up).
A12: Mean satisfaction at freshness 4 and 7 | B12: =TEXT(ANOVA!C9,"0.00")&" and "&TEXT(ANOVA!C12,"0.00") -> 3.99 and 5.51 | C12: Practical importance: more than a full scale step between the lowest and highest freshness ratings.
A13: Welch F (p) | B13: =TEXT(ANOVA!B38,"0.00")&" (p = "&TEXT(ANOVA!B41,"0.0E+00")&")" -> 80.89 (p = 6.2E-33) | C13: Same conclusion without assuming equal variances.
A14: Kruskal-Wallis H (p) | B14: =TEXT(ANOVA!B47,"0.00")&" (p = "&TEXT(ANOVA!B49,"0.0E+00")&")" -> 129.79 (p = 6.0E-28) | C14: Same conclusion without assuming normality.
A15: Conclusion | B15: =ANOVA!B32 -> Reject H0: mean satisfaction differs across freshness levels | C15: Survey data: this shows association, not cause. Freshness overlaps with taste (r = 0.79). Next step: separate freshness from taste.

Sheet AI Appendix
A1: Appendix: AI Tools and Prompts
A3: Tool: Claude Code (Anthropic), model Claude Opus 5.5, run on my own computer. It wrote the Python code and these Excel formulas, ran them, and drafted the explanations.
A4: Prompt 1 (paraphrased): build the M2-Technical in a full version with executed code and a 'how to defend this' note beside each metric, p-value and chart, plus an AI appendix; a practice version with the work removed but instructions, hints and checks kept; and a one-page instruction sheet.
A5: Prompt 2: my answers to its questions: the dataset is Customer_Satisfaction.xlsx, I do the whole analysis, deliver a Jupyter notebook and an Excel workbook.
A6: Output: cleaning checks, correlation analysis, one-way ANOVA with assumption checks, Welch's ANOVA, Kruskal-Wallis, charts, report and Q&A drafts.
A7: Verification 1: every value in this workbook was compared with the Python notebook; they match (Welch p differs only in far decimals because Excel rounds df2 down).
A8: Verification 2: SS between + SS within = SS total (row 30 of the ANOVA sheet is 0).
A9: Verification 3: the Python ANOVA computed by hand matched SciPy's built-in f_oneway exactly.
A10: Correction 1: SciPy's Levene test defaults to median-centering; it was switched to mean-centering so Python and Excel compute the same statistic. Both show unequal variances.
A11: Correction 2: the task-note columns in the raw sheet were excluded from the data.
A12: Correction 3: after the assumption checks failed, Welch's ANOVA and Kruskal-Wallis were added; the conclusion rests on all three tests agreeing.
